Using Application HELLO
WARNING: Caught exception while running HELLO test-case Test changing state to UNRUNNABLE :
Traceback (most recent call last):
  File "/users/geoff/work/master/Testing/TextTest/lib/default/actionrunner.py", line 240, in handleExceptions
    method(*args)
  File "/carm/proj/texttest-tmp/geoff/texttest.14Apr103501.6186/texttest.sge/QueueSystems/ErrorHandling/Console/SlaveCrash/customconfig.py", line 18, in __call__
    wibble
NameError: global name 'wibble' is not defined
